Workbook

Sheet Read me
A1: MedBrains — role test cases
A3: Why: signed in as an administrator you see every screen. These cases check what each role really sees and does.
A4: 35 roles, 568 cases. One tab per role; the Summary tab totals results.
A6: How to test
A7: 1. Take your role's username and password from the test-accounts file (shared via the password manager).
A8: 2. Sign in at app.medbrains.in with hospital code AMH.
A9: 3. Work down your role's tab. Set Result to Pass, Fail, Blocked (could not test) or leave Not run. Add your name and date.
A10: 4. For every Fail: write what you saw in Notes, take a screenshot, and report it with the case ID.
A12: Case types
A13: Sign in — the account works.
A14: Should see — every screen this role's permissions open.
A15: Must not see — screens hidden from this role, and refused even when the address is typed.
... A19: Generated from the code by scripts/generate_role_test_cases.py — regenerate after permission or menu changes.

Sheet Summary
A1: Role | B1: Login | C1: Permissions | D1: Cases | E1: Pass | F1: Fail | G1: Blocked | H1: Not run
A2: Doctor | B2: test_doctor | C2: 301 | D2: 54 | E2: =COUNTIF('Doctor'!H2:H55,"Pass") | F2: =COUNTIF('Doctor'!H2:H55,"Fail") | G2: =COUNTIF('Doctor'!H2:H55,"Blocked") | H2: =COUNTIF('Doctor'!H2:H55,"Not run")
A3: Nurse | B3: test_nurse | C3: 221 | D3: 47 | E3: =COUNTIF('Nurse'!H2:H48,"Pass") | F3: =COUNTIF('Nurse'!H2:H48,"Fail") | G3: =COUNTIF('Nurse'!H2:H48,"Blocked") | H3: =COUNTIF('Nurse'!H2:H48,"Not run")
A4: Receptionist | B4: test_receptionist | C4: 71 | D4: 31 | E4: =COUNTIF('Receptionist'!H2:H32,"Pass") | F4: =COUNTIF('Receptionist'!H2:H32,"Fail") | G4: =COUNTIF('Receptionist'!H2:H32,"Blocked") | H4: =COUNTIF('Receptionist'!H2:H32,"Not run")
A5: Lab Technician | B5: test_lab_technician | C5: 36 | D5: 16 | E5: =COUNTIF('Lab Technician'!H2:H17,"Pass") | F5: =COUNTIF('Lab Technician'!H2:H17,"Fail") | G5: =COUNTIF('Lab Technician'!H2:H17,"Blocked") | H5: =COUNTIF('Lab Technician'!H2:H17,"Not run")
A6: Pharmacist | B6: test_pharmacist | C6: 85 | D6: 24 | E6: =COUNTIF('Pharmacist'!H2:H25,"Pass") | F6: =COUNTIF('Pharmacist'!H2:H25,"Fail") | G6: =COUNTIF('Pharmacist'!H2:H25,"Blocked") | H6: =COUNTIF('Pharmacist'!H2:H25,"Not run")
A7: Billing Clerk | B7: test_billing_clerk | C7: 81 | D7: 24 | E7: =COUNTIF('Billing Clerk'!H2:H25,"Pass") | F7: =COUNTIF('Billing Clerk'!H2:H25,"Fail") | G7: =COUNTIF('Billing Clerk'!H2:H25,"Blocked") | H7: =COUNTIF('Billing Clerk'!H2:H25,"Not run")
A8: Housekeeping Staff | B8: test_housekeeping_staff | C8: 14 | D8: 12 | E8: =COUNTIF('Housekeeping Staff'!H2:H13,"Pass") | F8: =COUNTIF('Housekeeping Staff'!H2:H13,"Fail") | G8: =COUNTIF('Housekeeping Staff'!H2:H13,"Blocked") | H8: =COUNTIF('Housekeeping Staff'!H2:H13,"Not run")
A9: Facilities Manager | B9: test_facilities_manager | C9: 108 | D9: 21 | E9: =COUNTIF('Facilities Manager'!H2:H22,"Pass") | F9: =COUNTIF('Facilities Manager'!H2:H22,"Fail") | G9: =COUNTIF('Facilities Manager'!H2:H22,"Blocked") | H9: =COUNTIF('Facilities Manager'!H2:H22,"Not run")
A10: Audit Officer | B10: test_audit_officer | C10: 63 | D10: 27 | E10: =COUNTIF('Audit Officer'!H2:H28,"Pass") | F10: =COUNTIF('Audit Officer'!H2:H28,"Fail") | G10: =COUNTIF('Audit Officer'!H2:H28,"Blocked") | H10: =COUNTIF('Audit Officer'!H2:H28,"Not run")
A11: Quality Officer | B11: test_quality_officer | C11: 45 | D11: 19 | E11: =COUNTIF('Quality Officer'!H2:H20,"Pass") | F11: =COUNTIF('Quality Officer'!H2:H20,"Fail") | G11: =COUNTIF('Quality Officer'!H2:H20,"Blocked") | H11: =COUNTIF('Quality Officer'!H2:H20,"Not run")
A12: Occupational Health Officer | B12: test_occ_health_officer | C12: 12 | D12: 11 | E12: =COUNTIF('Occupational Health Officer'!H2:H12,"Pass") | F12: =COUNTIF('Occupational Health Officer'!H2:H12,"Fail") | G12: =COUNTIF('Occupational Health Officer'!H2:H12,"Blocked") | H12: =COUNTIF('Occupational Health Officer'!H2:H12,"Not run")
A13: Utilization Reviewer | B13: test_utilization_reviewer | C13: 9 | D13: 11 | E13: =COUNTIF('Utilization Reviewer'!H2:H12,"Pass") | F13: =COUNTIF('Utilization Reviewer'!H2:H12,"Fail") | G13: =COUNTIF('Utilization Reviewer'!H2:H12,"Blocked") | H13: =COUNTIF('Utilization Reviewer'!H2:H12,"Not run")
A14: Case Manager | B14: test_case_manager | C14: 10 | D14: 11 | E14: =COUNTIF('Case Manager'!H2:H12,"Pass") | F14: =COUNTIF('Case Manager'!H2:H12,"Fail") | G14: =COUNTIF('Case Manager'!H2:H12,"Blocked") | H14: =COUNTIF('Case Manager'!H2:H12,"Not run")
A15: Scheduling Admin | B15: test_scheduling_admin | C15: 12 | D15: 13 | E15: =COUNTIF('Scheduling Admin'!H2:H14,"Pass") | F15: =COUNTIF('Scheduling Admin'!H2:H14,"Fail") | G15: =COUNTIF('Scheduling Admin'!H2:H14,"Blocked") | H15: =COUNTIF('Scheduling Admin'!H2:H14,"Not run")
A16: MRD Officer | B16: test_mrd_officer | C16: 25 | D16: 16 | E16: =COUNTIF('MRD Officer'!H2:H17,"Pass") | F16: =COUNTIF('MRD Officer'!H2:H17,"Fail") | G16: =COUNTIF('MRD Officer'!H2:H17,"Blocked") | H16: =COUNTIF('MRD Officer'!H2:H17,"Not run")
A17: Canteen Staff | B17: test_canteen_staff | C17: 7 | D17: 11 | E17: =COUNTIF('Canteen Staff'!H2:H12,"Pass") | F17: =COUNTIF('Canteen Staff'!H2:H12,"Fail") | G17: =COUNTIF('Canteen Staff'!H2:H12,"Blocked") | H17: =COUNTIF('Canteen Staff'!H2:H12,"Not run")
A18: Dietitian | B18: test_dietitian | C18: 15 | D18: 11 | E18: =COUNTIF('Dietitian'!H2:H12,"Pass") | F18: =COUNTIF('Dietitian'!H2:H12,"Fail") | G18: =COUNTIF('Dietitian'!H2:H12,"Blocked") | H18: =COUNTIF('Dietitian'!H2:H12,"Not run")
A19: Security Guard | B19: test_security_guard | C19: 18 | D19: 12 | E19: =COUNTIF('Security Guard'!H2:H13,"Pass") | F19: =COUNTIF('Security Guard'!H2:H13,"Fail") | G19: =COUNTIF('Security Guard'!H2:H13,"Blocked") | H19: =COUNTIF('Security Guard'!H2:H13,"Not run")
A20: Biomedical Engineer | B20: test_biomed_engineer | C20: 31 | D20: 14 | E20: =COUNTIF('Biomedical Engineer'!H2:H15,"Pass") | F20: =COUNTIF('Biomedical Engineer'!H2:H15,"Fail") | G20: =COUNTIF('Biomedical Engineer'!H2:H15,"Blocked") | H20: =COUNTIF('Biomedical Engineer'!H2:H15,"Not run")
A21: Ambulance Driver | B21: test_ambulance_driver | C21: 12 | D21: 11 | E21: =COUNTIF('Ambulance Driver'!H2:H12,"Pass") | F21: =COUNTIF('Ambulance Driver'!H2:H12,"Fail") | G21: =COUNTIF('Ambulance Driver'!H2:H12,"Blocked") | H21: =COUNTIF('Ambulance Driver'!H2:H12,"Not run")
A22: Radiology Technician | B22: test_radiology_tech | C22: 11 | D22: 12 | E22: =COUNTIF('Radiology Technician'!H2:H13,"Pass") | F22: =COUNTIF('Radiology Technician'!H2:H13,"Fail") | G22: =COUNTIF('Radiology Technician'!H2:H13,"Blocked") | H22: =COUNTIF('Radiology Technician'!H2:H13,"Not run")
A23: CSSD Technician | B23: test_cssd_technician | C23: 13 | D23: 11 | E23: =COUNTIF('CSSD Technician'!H2:H12,"Pass") | F23: =COUNTIF('CSSD Technician'!H2:H12,"Fail") | G23: =COUNTIF('CSSD Technician'!H2:H12,"Blocked") | H23: =COUNTIF('CSSD Technician'!H2:H12,"Not run")
A24: Blood Bank Technician | B24: test_blood_bank_tech | C24: 14 | D24: 11 | E24: =COUNTIF('Blood Bank Technician'!H2:H12,"Pass") | F24: =COUNTIF('Blood Bank Technician'!H2:H12,"Fail") | G24: =COUNTIF('Blood Bank Technician'!H2:H12,"Blocked") | H24: =COUNTIF('Blood Bank Technician'!H2:H12,"Not run")
A25: Marketing Executive | B25: test_marketing_executive | C25: 13 | D25: 12 | E25: =COUNTIF('Marketing Executive'!H2:H13,"Pass") | F25: =COUNTIF('Marketing Executive'!H2:H13,"Fail") | G25: =COUNTIF('Marketing Executive'!H2:H13,"Blocked") | H25: =COUNTIF('Marketing Executive'!H2:H13,"Not run")
A26: Front Office Staff | B26: test_front_office_staff | C26: 46 | D26: 17 | E26: =COUNTIF('Front Office Staff'!H2:H18,"Pass") | F26: =COUNTIF('Front Office Staff'!H2:H18,"Fail") | G26: =COUNTIF('Front Office Staff'!H2:H18,"Blocked") | H26: =COUNTIF('Front Office Staff'!H2:H18,"Not run")
A27: Infection Control Officer | B27: test_infection_control_officer | C27: 16 | D27: 11 | E27: =COUNTIF('Infection Control Officer'!H2:H12,"Pass") | F27: =COUNTIF('Infection Control Officer'!H2:H12,"Fail") | G27: =COUNTIF('Infection Control Officer'!H2:H12,"Blocked") | H27: =COUNTIF('Infection Control Officer'!H2:H12,"Not run")
A28: Procurement Officer | B28: test_procurement_officer | C28: 16 | D28: 12 | E28: =COUNTIF('Procurement Officer'!H2:H13,"Pass") | F28: =COUNTIF('Procurement Officer'!H2:H13,"Fail") | G28: =COUNTIF('Procurement Officer'!H2:H13,"Blocked") | H28: =COUNTIF('Procurement Officer'!H2:H13,"Not run")
A29: Store Keeper | B29: test_store_keeper | C29: 25 | D29: 12 | E29: =COUNTIF('Store Keeper'!H2:H13,"Pass") | F29: =COUNTIF('Store Keeper'!H2:H13,"Fail") | G29: =COUNTIF('Store Keeper'!H2:H13,"Blocked") | H29: =COUNTIF('Store Keeper'!H2:H13,"Not run")
A30: HR Officer | B30: test_hr_officer | C30: 17 | D30: 12 | E30: =COUNTIF('HR Officer'!H2:H13,"Pass") | F30: =COUNTIF('HR Officer'!H2:H13,"Fail") | G30: =COUNTIF('HR Officer'!H2:H13,"Blocked") | H30: =COUNTIF('HR Officer'!H2:H13,"Not run")
A31: Camp Coordinator | B31: test_camp_coordinator | C31: 25 | D31: 12 | E31: =COUNTIF('Camp Coordinator'!H2:H13,"Pass") | F31: =COUNTIF('Camp Coordinator'!H2:H13,"Fail") | G31: =COUNTIF('Camp Coordinator'!H2:H13,"Blocked") | H31: =COUNTIF('Camp Coordinator'!H2:H13,"Not run")
A32: Insurance Officer | B32: test_insurance_officer | C32: 11 | D32: 11 | E32: =COUNTIF('Insurance Officer'!H2:H12,"Pass") | F32: =COUNTIF('Insurance Officer'!H2:H12,"Fail") | G32: =COUNTIF('Insurance Officer'!H2:H12,"Blocked") | H32: =COUNTIF('Insurance Officer'!H2:H12,"Not run")
A33: Wall Display | B33: test_display_device | C33: 1 | D33: 8 | E33: =COUNTIF('Wall Display'!H2:H9,"Pass") | F33: =COUNTIF('Wall Display'!H2:H9,"Fail") | G33: =COUNTIF('Wall Display'!H2:H9,"Blocked") | H33: =COUNTIF('Wall Display'!H2:H9,"Not run")
A34: OT Staff | B34: test_ot_staff | C34: 20 | D34: 11 | E34: =COUNTIF('OT Staff'!H2:H12,"Pass") | F34: =COUNTIF('OT Staff'!H2:H12,"Fail") | G34: =COUNTIF('OT Staff'!H2:H12,"Blocked") | H34: =COUNTIF('OT Staff'!H2:H12,"Not run")
A35: Delivery runner | B35: test_delivery_runner | C35: 4 | D35: 11 | E35: =COUNTIF('Delivery runner'!H2:H12,"Pass") | F35: =COUNTIF('Delivery runner'!H2:H12,"Fail") | G35: =COUNTIF('Delivery runner'!H2:H12,"Blocked") | H35: =COUNTIF('Delivery runner'!H2:H12,"Not run")
A36: Staff (awaiting role) | B36: test_staff | C36: 2 | D36: 9 | E36: =COUNTIF('Staff (awaiting role)'!H2:H10,"Pass") | F36: =COUNTIF('Staff (awaiting role)'!H2:H10,"Fail") | G36: =COUNTIF('Staff (awaiting role)'!H2:H10,"Blocked") | H36: =COUNTIF('Staff (awaiting role)'!H2:H10,"Not run")

Sheet Doctor
A1: Case | B1: Type | C1: Area | D1: What to test | E1: Steps | F1: Expected | G1: Permission | H1: Result | I1: Tester | J1: Date | K1: Notes
A2: doctor:sign-in | B2: Sign in | C2: Sign in | D2: Sign in as Doctor | E2: app.medbrains.in → hospital code AMH → username test_doctor and the password from your test-accounts file. | F2: You are signed in; the header shows 'TEST - Doctor'; you land on a page you can use (not an error). | H2: Not run
A3: doctor:see:/dashboard | B3: Should see | C3: Core | D3: Open Dashboard | E3: Menu → Core → Dashboard (/dashboard) | F3: The screen opens with no 'access denied' or error message. Lists load; an empty list says so. Buttons to add or change things appear only where this role should do that. | G3: dashboard.view | H3: Not run
A4: doctor:see:/approvals | B4: Should see | C4: Core | D4: Open Approvals | E4: Menu → Core → Approvals (/approvals) | F4: The screen opens with no 'access denied' or error message. Lists load; an empty list says so. Buttons to add or change things appear only where this role should do that. | H4: Not run
A5: doctor:see:/health-pulse | B5: Should see | C5: Core | D5: Open Health Pulse | E5: Menu → Core → Health Pulse (/health-pulse) | F5: The screen opens with no 'access denied' or error message. Lists load; an empty list says so. Buttons to add or change things appear only where this role should do that. | G5: dashboard.view | H5: Not run
A6: doctor:see:/patients | B6: Should see | C6: Clinical | D6: Open Patients | E6: Menu → Clinical → Patients (/patients) | F6: The screen opens with no 'access denied' or error message. Lists load; an empty list says so. Buttons to add or change things appear only where this role should do that. | G6: patients.list | H6: Not run
A7: doctor:see:/opd | B7: Should see | C7: Clinical | D7: Open OPD Queue | E7: Menu → Clinical → OPD Queue (/opd) | F7: The screen opens with no 'access denied' or error message. Lists load; an empty list says so. Buttons to add or change things appear only where this role should do that. | G7: opd.queue.list | H7: Not run
A8: doctor:see:/telemedicine | B8: Should see | C8: Clinical | D8: Open Telemedicine | E8: Menu → Clinical → Telemedicine (/telemedicine) | F8: The screen opens with no 'access denied' or error message. Lists load; an empty list says so. Buttons to add or change things appear only where this role should do that. | G8: opd.queue.view | H8: Not run
A9: doctor:see:/doctor/signoffs | B9: Should see | C9: Clinical | D9: Open Doctor Sign-offs | E9: Menu → Clinical → Doctor Sign-offs (/doctor/signoffs) | F9: The screen opens with no 'access denied' or error message. Lists load; an empty list says so. Buttons to add or change things appear only where this role should do that. | G9: doctor.signoffs.view_own | H9: Not run
A10: doctor:see:/emergency | B10: Should see | C10: Clinical | D10: Open Emergency | E10: Menu → Clinical → Emergency (/emergency) | F10: The screen opens with no 'access denied' or error message. Lists load; an empty list says so. Buttons to add or change things appear only where this role should do that. | G10: emergency.visits.list | H10: Not run
A11: doctor:see:/order-sets | B11: Should see | C11: Clinical | D11: Open Order Sets | E11: Menu → Clinical → Order Sets (/order-sets) | F11: The screen opens with no 'access denied' or error message. Lists load; an empty list says so. Buttons to add or change things appear only where this role should do that. | G11: order_sets.templates.list | H11: Not run
A12: doctor:see:/chronic-care | B12: Should see | C12: Clinical | D12: Open Chronic Care | E12: Menu → Clinical → Chronic Care (/chronic-care) | F12: The screen opens with no 'access denied' or error message. Lists load; an empty list says so. Buttons to add or change things appear only where this role should do that. | G12: chronic.enrollments.list | H12: Not run
A13: doctor:see:/home-healthcare | B13: Should see | C13: Clinical | D13: Open Home healthcare | E13: Menu → Clinical → Home healthcare (/home-healthcare) | F13: The screen opens with no 'access denied' or error message. Lists load; an empty list says so. Buttons to add or change things appear only where this role should do that. | G13: home_health.list | H13: Not run
A14: doctor:see:/home-visits | B14: Should see | C14: Clinical | D14: Open Home visits | E14: Menu → Clinical → Home visits (/home-visits) | F14: The screen opens with no 'access denied' or error message. Lists load; an empty list says so. Buttons to add or change things appear only where this role should do that. | G14: home_health.list | H14: Not run
A15: doctor:see:/lab | B15: Should see | C15: Diagnostics | D15: Open Lab | E15: Menu → Diagnostics → Lab (/lab) | F15: The screen opens with no 'access denied' or error message. Lists load; an empty list says so. Buttons to add or change things appear only where this role should do that. (Hidden if the hospital has this module switched off.) | G15: lab.orders.list | H15: Not run
A16: doctor:see:/pharmacy | B16: Should see | C16: Diagnostics | D16: Open Pharmacy | E16: Menu → Diagnostics → Pharmacy (/pharmacy) | F16: The screen opens with no 'access denied' or error message. Lists load; an empty list says so. Buttons to add or change things appear only where this role should do that. | G16: pharmacy.prescriptions.list | H16: Not run
... A45: doctor:see:/admin/documents | B45: Should see | C45: Administration | D45: Open Documents & Printing | E45: Menu → Administration → Admin → Documents & Printing (/admin/documents) | F45: The screen opens with no 'access denied' or error message. Lists load; an empty list says so. Buttons to add or change things appear only where this role should do that. | G45: documents.templates.list | H45: Not run
A46: doctor:menu | B46: Must not see | C46: Menu | D46: Menu shows only this role's screens | E46: Look through every menu group. | F46: These must NOT be in the menu: Token Board, Token Console, Appointments, Radiology, Ward Stock, Pharmacy Finance, Fulfilment Queue, Home Deliveries, Collection Counter, Blood Bank, Nurse Activities, Diet & Kitchen, Billing, Procurement, Payroll, Smart Scheduling, Command Center, Communications, Camp Management, Ambulance, Housekeeping, CSSD, Facilities Management, Biomedical Engineering, Security, HR & Staffing, Clinical Knowledge, Directory, Hospital groups, Marketing, Health packages, Testimonials, Micro-site settings, Quality, Infection Control, Analytics & Dashboards, Audit Trail, Utilization Review, Case Management, Long-term care, Occupational Health, Users, Doctors, Roles & Permissions, Access Groups, Single Sign-On, Access Requests, NABH Indicators, Setup Center, Onboarding workbook, Settings, Document Templates, Built-in Pipelines, Forms, Test cycles, API keys, Webhooks, Retrospective Entry, Device Integration, Paired Devices, Queues, Message Simulator. | H46: Not run
A47: doctor:url:/admin/users | B47: Must not see | C47: Administration | D47: Typing the address of Users | E47: Type app.medbrains.in/admin/users into the address bar. | F47: You get an 'access denied' page or are sent back — none of that screen's data is shown, even briefly. | G47: admin.users.list | H47: Not run
A48: doctor:url:/audit | B48: Must not see | C48: Compliance | D48: Typing the address of Audit Trail | E48: Type app.medbrains.in/audit into the address bar. | F48: You get an 'access denied' page or are sent back — none of that screen's data is shown, even briefly. | G48: audit.log.view | H48: Not run
A49: doctor:url:/billing | B49: Must not see | C49: Finance | D49: Typing the address of Billing | E49: Type app.medbrains.in/billing into the address bar. | F49: You get an 'access denied' page or are sent back — none of that screen's data is shown, even briefly. | G49: billing.invoices.list | H49: Not run
A50: doctor:url:/hr/payroll | B50: Must not see | C50: Finance | D50: Typing the address of Payroll | E50: Type app.medbrains.in/hr/payroll into the address bar. | F50: You get an 'access denied' page or are sent back — none of that screen's data is shown, even briefly. | G50: hr.payroll.structures.list | H50: Not run
A51: doctor:wf:consult-a-patient-end-to-end | B51: Workflow | C51: OPD Queue | D51: Consult a patient end to end | E51: OPD Queue → call your next patient → Start → record complaint, examination, diagnosis (ICD-10 search), advice → prescribe two medicines → Complete. | F51: The visit is completed; the case sheet shows the note signed by you; the consultation is on the patient's bill at your fee. | H51: Not run
A52: doctor:wf:free-revisit-inside-the-window | B52: Workflow | C52: OPD Queue | D52: Free revisit inside the window | E52: (Billing settings has a free revisit window, e.g. 7 days.) Consult the same patient again within the window. | F52: The second consultation is billed ₹0, marked 'Free revisit (day N of M)'. | H52: Not run
A53: doctor:wf:order-a-lab-test-and-an-x-ray | B53: Workflow | C53: Orders | D53: Order a lab test and an X-ray | E53: In a visit, order a CBC and a chest X-ray. | F53: The CBC appears in Lab and the X-ray in Radiology as ordered for this patient. | H53: Not run
A54: doctor:wf:spectacle-prescription | B54: Workflow | C54: Ophthalmology | D54: Spectacle prescription | E54: In a visit: Specialty tab → Ophthalmology → New exam. Enter vision, sphere/cylinder/axis for both eyes, lens type. Sign prescription (it should ask for the pupillary distance first) → PDF → Spectacle prescription. | F54: Signing is refused until PD is entered; once signed the exam is read-only; the PDF shows your name and registration number, not DRAFT. | H54: Not run
A55: doctor:wf:clear-pending-sign-offs | B55: Workflow | C55: Doctor Sign-offs | D55: Clear pending sign-offs | E55: Doctor Sign-offs → open an unsigned note → sign. | F55: It leaves the pending list and shows as signed on the case sheet. | H55: Not run

Sheet Nurse
A1: Case | B1: Type | C1: Area | D1: What to test | E1: Steps | F1: Expected | G1: Permission | H1: Result | I1: Tester | J1: Date | K1: Notes
A2: nurse:sign-in | B2: Sign in | C2: Sign in | D2: Sign in as Nurse | E2: app.medbrains.in → hospital code AMH → username test_nurse and the password from your test-accounts file. | F2: You are signed in; the header shows 'TEST - Nurse'; you land on a page you can use (not an error). | H2: Not run
A3: nurse:see:/dashboard | B3: Should see | C3: Core | D3: Open Dashboard | E3: Menu → Core → Dashboard (/dashboard) | F3: The screen opens with no 'access denied' or error message. Lists load; an empty list says so. Buttons to add or change things appear only where this role should do that. | G3: dashboard.view | H3: Not run
A4: nurse:see:/approvals | B4: Should see | C4: Core | D4: Open Approvals | E4: Menu → Core → Approvals (/approvals) | F4: The screen opens with no 'access denied' or error message. Lists load; an empty list says so. Buttons to add or change things appear only where this role should do that. | H4: Not run
A5: nurse:see:/health-pulse | B5: Should see | C5: Core | D5: Open Health Pulse | E5: Menu → Core → Health Pulse (/health-pulse) | F5: The screen opens with no 'access denied' or error message. Lists load; an empty list says so. Buttons to add or change things appear only where this role should do that. | G5: dashboard.view | H5: Not run
A6: nurse:see:/patients | B6: Should see | C6: Clinical | D6: Open Patients | E6: Menu → Clinical → Patients (/patients) | F6: The screen opens with no 'access denied' or error message. Lists load; an empty list says so. Buttons to add or change things appear only where this role should do that. | G6: patients.list | H6: Not run
A7: nurse:see:/opd | B7: Should see | C7: Clinical | D7: Open OPD Queue | E7: Menu → Clinical → OPD Queue (/opd) | F7: The screen opens with no 'access denied' or error message. Lists load; an empty list says so. Buttons to add or change things appear only where this role should do that. | G7: opd.queue.list | H7: Not run
A8: nurse:see:/telemedicine | B8: Should see | C8: Clinical | D8: Open Telemedicine | E8: Menu → Clinical → Telemedicine (/telemedicine) | F8: The screen opens with no 'access denied' or error message. Lists load; an empty list says so. Buttons to add or change things appear only where this role should do that. | G8: opd.queue.view | H8: Not run
A9: nurse:see:/emergency | B9: Should see | C9: Clinical | D9: Open Emergency | E9: Menu → Clinical → Emergency (/emergency) | F9: The screen opens with no 'access denied' or error message. Lists load; an empty list says so. Buttons to add or change things appear only where this role should do that. | G9: emergency.visits.list | H9: Not run
A10: nurse:see:/chronic-care | B10: Should see | C10: Clinical | D10: Open Chronic Care | E10: Menu → Clinical → Chronic Care (/chronic-care) | F10: The screen opens with no 'access denied' or error message. Lists load; an empty list says so. Buttons to add or change things appear only where this role should do that. | G10: chronic.enrollments.list | H10: Not run
A11: nurse:see:/home-healthcare | B11: Should see | C11: Clinical | D11: Open Home healthcare | E11: Menu → Clinical → Home healthcare (/home-healthcare) | F11: The screen opens with no 'access denied' or error message. Lists load; an empty list says so. Buttons to add or change things appear only where this role should do that. | G11: home_health.list | H11: Not run
A12: nurse:see:/home-visits | B12: Should see | C12: Clinical | D12: Open Home visits | E12: Menu → Clinical → Home visits (/home-visits) | F12: The screen opens with no 'access denied' or error message. Lists load; an empty list says so. Buttons to add or change things appear only where this role should do that. | G12: home_health.list | H12: Not run
A13: nurse:see:/lab | B13: Should see | C13: Diagnostics | D13: Open Lab | E13: Menu → Diagnostics → Lab (/lab) | F13: The screen opens with no 'access denied' or error message. Lists load; an empty list says so. Buttons to add or change things appear only where this role should do that. (Hidden if the hospital has this module switched off.) | G13: lab.orders.list | H13: Not run
A14: nurse:see:/radiology | B14: Should see | C14: Diagnostics | D14: Open Radiology | E14: Menu → Diagnostics → Radiology (/radiology) | F14: The screen opens with no 'access denied' or error message. Lists load; an empty list says so. Buttons to add or change things appear only where this role should do that. (Hidden if the hospital has this module switched off.) | G14: radiology.orders.list | H14: Not run
A15: nurse:see:/pharmacy | B15: Should see | C15: Diagnostics | D15: Open Pharmacy | E15: Menu → Diagnostics → Pharmacy (/pharmacy) | F15: The screen opens with no 'access denied' or error message. Lists load; an empty list says so. Buttons to add or change things appear only where this role should do that. | G15: pharmacy.prescriptions.list | H15: Not run
A16: nurse:see:/ipd | B16: Should see | C16: Inpatient | D16: Open IPD | E16: Menu → Inpatient → IPD (/ipd) | F16: The screen opens with no 'access denied' or error message. Lists load; an empty list says so. Buttons to add or change things appear only where this role should do that. | G16: ipd.admissions.list | H16: Not run
... A39: nurse:see:/admin/documents | B39: Should see | C39: Administration | D39: Open Documents & Printing | E39: Menu → Administration → Admin → Documents & Printing (/admin/documents) | F39: The screen opens with no 'access denied' or error message. Lists load; an empty list says so. Buttons to add or change things appear only where this role should do that. | G39: documents.templates.list | H39: Not run
A40: nurse:menu | B40: Must not see | C40: Menu | D40: Menu shows only this role's screens | E40: Look through every menu group. | F40: These must NOT be in the menu: Token Board, Token Console, Appointments, Doctor Sign-offs, Order Sets, Ward Stock, Pharmacy Finance, Fulfilment Queue, Home Deliveries, Collection Counter, Blood Bank, Case sheet review, Operation Theatre, Diet & Kitchen, Billing, Insurance & TPA, Procurement, Payroll, Smart Scheduling, Command Center, Communications, Camp Management, Ambulance, Housekeeping, CSSD, Facilities Management, Biomedical Engineering, Security, HR & Staffing, Medical Records, Clinical Knowledge, Directory, Hospital groups, Marketing, Health packages, Testimonials, Micro-site settings, Quality, Infection Control, Consent Management, Analytics & Dashboards, Audit Trail, Utilization Review, Case Management, Clinical trials, Occupational Health, Users, Doctors, Roles & Permissions, Access Groups, Single Sign-On, Access Requests, NABH Indicators, Setup Center, Onboarding workbook, Settings, Document Templates, Built-in Pipelines, Forms, Test cycles, API keys, Webhooks, Doctor Schedules, Retrospective Entry, Device Integration, Paired Devices, Queues, Message Simulator. | H40: Not run
A41: nurse:url:/admin/users | B41: Must not see | C41: Administration | D41: Typing the address of Users | E41: Type app.medbrains.in/admin/users into the address bar. | F41: You get an 'access denied' page or are sent back — none of that screen's data is shown, even briefly. | G41: admin.users.list | H41: Not run
A42: nurse:url:/audit | B42: Must not see | C42: Compliance | D42: Typing the address of Audit Trail | E42: Type app.medbrains.in/audit into the address bar. | F42: You get an 'access denied' page or are sent back — none of that screen's data is shown, even briefly. | G42: audit.log.view | H42: Not run
A43: nurse:url:/billing | B43: Must not see | C43: Finance | D43: Typing the address of Billing | E43: Type app.medbrains.in/billing into the address bar. | F43: You get an 'access denied' page or are sent back — none of that screen's data is shown, even briefly. | G43: billing.invoices.list | H43: Not run
A44: nurse:url:/mrd | B44: Must not see | C44: Operations | D44: Typing the address of Medical Records | E44: Type app.medbrains.in/mrd into the address bar. | F44: You get an 'access denied' page or are sent back — none of that screen's data is shown, even briefly. | H44: Not run
A45: nurse:wf:record-vitals-before-the-doctor | B45: Workflow | C45: OPD Queue | D45: Record vitals before the doctor | E45: OPD Queue → a waiting patient → Vitals → enter BP, pulse, temperature, SpO2, weight. | F45: Vitals save; the doctor sees them on the visit; an out-of-range value is flagged. | H45: Not run
A46: nurse:wf:print-a-wristband-for-an-admitted-patient | B46: Workflow | C46: IPD | D46: Print a wristband for an admitted patient | E46: IPD → open an admission → Wristband → Send to print queue (or Generate & open PDF). | F46: With a wristband printer set up: 'Queued on <printer>' and the band prints with name, UHID and barcode. Without one: a clear 'no printer' message — never silence. | H46: Not run
A47: nurse:wf:give-a-scheduled-medicine-emar | B47: Workflow | C47: Nurse Activities | D47: Give a scheduled medicine (eMAR) | E47: Nurse Activities → medication round → scan or pick the patient → give a due dose. | F47: The dose is recorded with time and your name; giving it twice is warned. | H47: Not run
A48: nurse:wf:record-an-eye-workup-but-cannot-sign-it | B48: Workflow | C48: Ophthalmology | D48: Record an eye workup but cannot sign it | E48: Ophthalmology → New exam → enter vision and refraction → Save. | F48: Saved as a draft. There is NO 'Sign prescription' button for a nurse. | H48: Not run

Sheet Receptionist
A1: Case | B1: Type | C1: Area | D1: What to test | E1: Steps | F1: Expected | G1: Permission | H1: Result | I1: Tester | J1: Date | K1: Notes
A2: receptionist:sign-in | B2: Sign in | C2: Sign in | D2: Sign in as Receptionist | E2: app.medbrains.in → hospital code AMH → username test_receptionist and the password from your test-accounts file. | F2: You are signed in; the header shows 'TEST - Receptionist'; you land on a page you can use (not an error). | H2: Not run
A3: receptionist:see:/dashboard | B3: Should see | C3: Core | D3: Open Dashboard | E3: Menu → Core → Dashboard (/dashboard) | F3: The screen opens with no 'access denied' or error message. Lists load; an empty list says so. Buttons to add or change things appear only where this role should do that. | G3: dashboard.view | H3: Not run
A4: receptionist:see:/approvals | B4: Should see | C4: Core | D4: Open Approvals | E4: Menu → Core → Approvals (/approvals) | F4: The screen opens with no 'access denied' or error message. Lists load; an empty list says so. Buttons to add or change things appear only where this role should do that. | H4: Not run
A5: receptionist:see:/health-pulse | B5: Should see | C5: Core | D5: Open Health Pulse | E5: Menu → Core → Health Pulse (/health-pulse) | F5: The screen opens with no 'access denied' or error message. Lists load; an empty list says so. Buttons to add or change things appear only where this role should do that. | G5: dashboard.view | H5: Not run
A6: receptionist:see:/token-board | B6: Should see | C6: Core | D6: Open Token Board | E6: Menu → Core → Token Board (/token-board) | F6: The screen opens with no 'access denied' or error message. Lists load; an empty list says so. Buttons to add or change things appear only where this role should do that. | G6: front_office.queue.list | H6: Not run
A7: receptionist:see:/token-console | B7: Should see | C7: Core | D7: Open Token Console | E7: Menu → Core → Token Console (/token-console) | F7: The screen opens with no 'access denied' or error message. Lists load; an empty list says so. Buttons to add or change things appear only where this role should do that. | G7: front_office.queue.manage | H7: Not run
A8: receptionist:see:/patients | B8: Should see | C8: Clinical | D8: Open Patients | E8: Menu → Clinical → Patients (/patients) | F8: The screen opens with no 'access denied' or error message. Lists load; an empty list says so. Buttons to add or change things appear only where this role should do that. | G8: patients.list | H8: Not run
A9: receptionist:see:/opd | B9: Should see | C9: Clinical | D9: Open OPD Queue | E9: Menu → Clinical → OPD Queue (/opd) | F9: The screen opens with no 'access denied' or error message. Lists load; an empty list says so. Buttons to add or change things appear only where this role should do that. | G9: opd.queue.list | H9: Not run
A10: receptionist:see:/opd/appointments | B10: Should see | C10: Clinical | D10: Open Appointments | E10: Menu → Clinical → Appointments (/opd/appointments) | F10: The screen opens with no 'access denied' or error message. Lists load; an empty list says so. Buttons to add or change things appear only where this role should do that. | G10: opd.appointment.list | H10: Not run
A11: receptionist:see:/telemedicine | B11: Should see | C11: Clinical | D11: Open Telemedicine | E11: Menu → Clinical → Telemedicine (/telemedicine) | F11: The screen opens with no 'access denied' or error message. Lists load; an empty list says so. Buttons to add or change things appear only where this role should do that. | G11: opd.queue.view | H11: Not run
A12: receptionist:see:/emergency | B12: Should see | C12: Clinical | D12: Open Emergency | E12: Menu → Clinical → Emergency (/emergency) | F12: The screen opens with no 'access denied' or error message. Lists load; an empty list says so. Buttons to add or change things appear only where this role should do that. | G12: emergency.visits.list | H12: Not run
A13: receptionist:see:/billing | B13: Should see | C13: Finance | D13: Open Billing | E13: Menu → Finance → Billing (/billing) | F13: The screen opens with no 'access denied' or error message. Lists load; an empty list says so. Buttons to add or change things appear only where this role should do that. | G13: billing.invoices.list | H13: Not run
A14: receptionist:see:/insurance | B14: Should see | C14: Finance | D14: Open Insurance & TPA | E14: Menu → Finance → Insurance & TPA (/insurance) | F14: The screen opens with no 'access denied' or error message. Lists load; an empty list says so. Buttons to add or change things appear only where this role should do that. | G14: insurance.verification.list | H14: Not run
A15: receptionist:see:/front-office | B15: Should see | C15: Operations | D15: Open Front Office | E15: Menu → Operations → Front Office (/front-office) | F15: The screen opens with no 'access denied' or error message. Lists load; an empty list says so. Buttons to add or change things appear only where this role should do that. | G15: front_office.visitors.list, front_office.visitors.create, front_office.visitors.manage… | H15: Not run
A16: receptionist:see:/camp | B16: Should see | C16: Operations | D16: Open Camp Management | E16: Menu → Operations → Camp Management (/camp) | F16: The screen opens with no 'access denied' or error message. Lists load; an empty list says so. Buttons to add or change things appear only where this role should do that. | G16: camp.list | H16: Not run
... A23: receptionist:see:/admin/queues | B23: Should see | C23: Administration | D23: Open Queues | E23: Menu → Administration → Admin → Queues (/admin/queues) | F23: The screen opens with no 'access denied' or error message. Lists load; an empty list says so. Buttons to add or change things appear only where this role should do that. | G23: front_office.queue.config.view | H23: Not run
A24: receptionist:menu | B24: Must not see | C24: Menu | D24: Menu shows only this role's screens | E24: Look through every menu group. | F24: These must NOT be in the menu: Doctor Sign-offs, Order Sets, Chronic Care, Home healthcare, Home visits, Lab, Radiology, Ward Stock, Pharmacy, Pharmacy Finance, Fulfilment Queue, Home Deliveries, Collection Counter, Blood Bank, IPD, Care View, Case sheet review, ICU, Nurse Activities, Operation Theatre, Diet & Kitchen, Bedside Portal, Procurement, Indent & Store, Materials, Payroll, Smart Scheduling, Command Center, Communications, Ambulance, Housekeeping, CSSD, Facilities Management, Biomedical Engineering, Security, HR & Staffing, Medical Records, Clinical Knowledge, Directory, Hospital groups, Inter-hospital transfers, Inter-hospital stock, Quality, Infection Control, Consent Management, Regulatory Compliance, Analytics & Dashboards, Reports Center, Audit Trail, Utilization Review, Case Management, Ophthalmology, Dental, Cath Lab, Endoscopy, Psychiatry, Physical Medicine, Palliative Care, Maternity, Other Specialties, Clinical trials, Long-term care, Occupational Health, Users, Doctors, Roles & Permissions, Access Groups, Single Sign-On, Access Requests, NABH Indicators, Setup Center, Onboarding workbook, Settings, Document Templates, Built-in Pipelines, Forms, Test cycles, API keys, Webhooks, Doctor Schedules, Retrospective Entry, Device Integration, Paired Devices, Message Simulator. | H24: Not run
A25: receptionist:url:/admin/users | B25: Must not see | C25: Administration | D25: Typing the address of Users | E25: Type app.medbrains.in/admin/users into the address bar. | F25: You get an 'access denied' page or are sent back — none of that screen's data is shown, even briefly. | G25: admin.users.list | H25: Not run
A26: receptionist:url:/audit | B26: Must not see | C26: Compliance | D26: Typing the address of Audit Trail | E26: Type app.medbrains.in/audit into the address bar. | F26: You get an 'access denied' page or are sent back — none of that screen's data is shown, even briefly. | G26: audit.log.view | H26: Not run
A27: receptionist:url:/mrd | B27: Must not see | C27: Operations | D27: Typing the address of Medical Records | E27: Type app.medbrains.in/mrd into the address bar. | F27: You get an 'access denied' page or are sent back — none of that screen's data is shown, even briefly. | H27: Not run
A28: receptionist:url:/pharmacy | B28: Must not see | C28: Diagnostics | D28: Typing the address of Pharmacy | E28: Type app.medbrains.in/pharmacy into the address bar. | F28: You get an 'access denied' page or are sent back — none of that screen's data is shown, even briefly. | G28: pharmacy.prescriptions.list | H28: Not run
A29: receptionist:wf:register-a-new-patient | B29: Workflow | C29: Patients | D29: Register a new patient | E29: Patients → Register. Enter name, sex, date of birth, phone, address. Save. | F29: A UHID is issued and shown. Searching the name or phone in Patients finds them. | H29: Not run
A30: receptionist:wf:duplicate-check-on-registration | B30: Workflow | C30: Patients | D30: Duplicate check on registration | E30: Register the same name + phone + date of birth again. | F30: The system warns of a possible duplicate before saving a second record. | H30: Not run
A31: receptionist:wf:start-an-opd-visit-with-a-token | B31: Workflow | C31: OPD Queue | D31: Start an OPD visit with a token | E31: OPD Queue → new visit for the patient registered above. Pick a department and doctor. | F31: A token number is issued; the patient appears in the OPD queue as waiting; a token slip can be printed. | H31: Not run
A32: receptionist:wf:book-and-check-in-an-appointment | B32: Workflow | C32: Appointments | D32: Book and check in an appointment | E32: Appointments → book a slot with a doctor for tomorrow; then for today, and check the patient in. | F32: The slot shows as booked; on check-in the patient joins that doctor's queue. | H32: Not run

Sheet Lab Technician
A1: Case | B1: Type | C1: Area | D1: What to test | E1: Steps | F1: Expected | G1: Permission | H1: Result | I1: Tester | J1: Date | K1: Notes
A2: lab_technician:sign-in | B2: Sign in | C2: Sign in | D2: Sign in as Lab Technician | E2: app.medbrains.in → hospital code AMH → username test_lab_technician and the password from your test-accounts file. | F2: You are signed in; the header shows 'TEST - Lab Technician'; you land on a page you can use (not an error). | H2: Not run
A3: lab_technician:see:/dashboard | B3: Should see | C3: Core | D3: Open Dashboard | E3: Menu → Core → Dashboard (/dashboard) | F3: The screen opens with no 'access denied' or error message. Lists load; an empty list says so. Buttons to add or change things appear only where this role should do that. | G3: dashboard.view | H3: Not run
A4: lab_technician:see:/approvals | B4: Should see | C4: Core | D4: Open Approvals | E4: Menu → Core → Approvals (/approvals) | F4: The screen opens with no 'access denied' or error message. Lists load; an empty list says so. Buttons to add or change things appear only where this role should do that. | H4: Not run
A5: lab_technician:see:/health-pulse | B5: Should see | C5: Core | D5: Open Health Pulse | E5: Menu → Core → Health Pulse (/health-pulse) | F5: The screen opens with no 'access denied' or error message. Lists load; an empty list says so. Buttons to add or change things appear only where this role should do that. | G5: dashboard.view | H5: Not run
A6: lab_technician:see:/lab | B6: Should see | C6: Diagnostics | D6: Open Lab | E6: Menu → Diagnostics → Lab (/lab) | F6: The screen opens with no 'access denied' or error message. Lists load; an empty list says so. Buttons to add or change things appear only where this role should do that. (Hidden if the hospital has this module switched off.) | G6: lab.orders.list | H6: Not run
A7: lab_technician:see:/front-office | B7: Should see | C7: Operations | D7: Open Front Office | E7: Menu → Operations → Front Office (/front-office) | F7: The screen opens with no 'access denied' or error message. Lists load; an empty list says so. Buttons to add or change things appear only where this role should do that. | G7: front_office.visitors.list, front_office.visitors.create, front_office.visitors.manage… | H7: Not run
A8: lab_technician:see:/lms | B8: Should see | C8: Operations | D8: Open Learning (LMS) | E8: Menu → Operations → Learning (LMS) (/lms) | F8: The screen opens with no 'access denied' or error message. Lists load; an empty list says so. Buttons to add or change things appear only where this role should do that. | G8: lms.my_learning.view | H8: Not run
A9: lab_technician:see:/reports | B9: Should see | C9: Compliance | D9: Open Reports Center | E9: Menu → Compliance → Reports Center (/reports) | F9: The screen opens with no 'access denied' or error message. Lists load; an empty list says so. Buttons to add or change things appear only where this role should do that. | G9: analytics.view, billing.reports.view, quality.indicators.list… | H9: Not run
A10: lab_technician:see:/admin/documents | B10: Should see | C10: Administration | D10: Open Documents & Printing | E10: Menu → Administration → Admin → Documents & Printing (/admin/documents) | F10: The screen opens with no 'access denied' or error message. Lists load; an empty list says so. Buttons to add or change things appear only where this role should do that. | G10: documents.templates.list | H10: Not run
A11: lab_technician:menu | B11: Must not see | C11: Menu | D11: Menu shows only this role's screens | E11: Look through every menu group. | F11: These must NOT be in the menu: Token Board, Token Console, Patients, OPD Queue, Appointments, Telemedicine, Doctor Sign-offs, Emergency, Order Sets, Chronic Care, Home healthcare, Home visits, Radiology, Ward Stock, Pharmacy, Pharmacy Finance, Fulfilment Queue, Home Deliveries, Collection Counter, Blood Bank, IPD, Care View, Case sheet review, ICU, Nurse Activities, Operation Theatre, Diet & Kitchen, Bedside Portal, Billing, Insurance & TPA, Procurement, Indent & Store, Materials, Payroll, Smart Scheduling, Command Center, Communications, Camp Management, Ambulance, Housekeeping, CSSD, Facilities Management, Biomedical Engineering, Security, HR & Staffing, Medical Records, Clinical Knowledge, Directory, Hospital groups, Inter-hospital transfers, Inter-hospital stock, Marketing, Health packages, Testimonials, Micro-site settings, Quality, Infection Control, Consent Management, Regulatory Compliance, Analytics & Dashboards, Audit Trail, Utilization Review, Case Management, Ophthalmology, Dental, Cath Lab, Endoscopy, Psychiatry, Physical Medicine, Palliative Care, Maternity, Other Specialties, Clinical trials, Long-term care, Occupational Health, Users, Doctors, Roles & Permissions, Access Groups, Single Sign-On, Access Requests, NABH Indicators, Setup Center, Onboarding workbook, Settings, Document Templates, Built-in Pipelines, Forms, Test cycles, API keys, Webhooks, Doctor Schedules, Retrospective Entry, Device Integration, Paired Devices, Queues, Message Simulator. | H11: Not run
A12: lab_technician:url:/admin/users | B12: Must not see | C12: Administration | D12: Typing the address of Users | E12: Type app.medbrains.in/admin/users into the address bar. | F12: You get an 'access denied' page or are sent back — none of that screen's data is shown, even briefly. | G12: admin.users.list | H12: Not run
A13: lab_technician:url:/audit | B13: Must not see | C13: Compliance | D13: Typing the address of Audit Trail | E13: Type app.medbrains.in/audit into the address bar. | F13: You get an 'access denied' page or are sent back — none of that screen's data is shown, even briefly. | G13: audit.log.view | H13: Not run
A14: lab_technician:url:/billing | B14: Must not see | C14: Finance | D14: Typing the address of Billing | E14: Type app.medbrains.in/billing into the address bar. | F14: You get an 'access denied' page or are sent back — none of that screen's data is shown, even briefly. | G14: billing.invoices.list | H14: Not run
A15: lab_technician:url:/mrd | B15: Must not see | C15: Operations | D15: Typing the address of Medical Records | E15: Type app.medbrains.in/mrd into the address bar. | F15: You get an 'access denied' page or are sent back — none of that screen's data is shown, even briefly. | H15: Not run
A16: lab_technician:wf:collect-a-sample-with-a-barcode | B16: Workflow | C16: Lab | D16: Collect a sample with a barcode | E16: (As test_doctor, order a CBC.) Lab → the order → Collect sample → scan/enter the patient's UHID and a tube barcode. | F16: Collection refuses a wrong UHID; on success the order shows 'sample collected' with the barcode. | H16: Not run
A17: lab_technician:wf:enter-and-verify-results | B17: Workflow | C17: Lab | D17: Enter and verify results | E17: Lab → the collected order → enter results → verify. | F17: Values outside range are flagged H/L; the doctor sees the verified result on the visit; a critical value raises an alert. | H17: Not run

Sheet Pharmacist
A1: Case | B1: Type | C1: Area | D1: What to test | E1: Steps | F1: Expected | G1: Permission | H1: Result | I1: Tester | J1: Date | K1: Notes
A2: pharmacist:sign-in | B2: Sign in | C2: Sign in | D2: Sign in as Pharmacist | E2: app.medbrains.in → hospital code AMH → username test_pharmacist and the password from your test-accounts file. | F2: You are signed in; the header shows 'TEST - Pharmacist'; you land on a page you can use (not an error). | H2: Not run
A3: pharmacist:see:/dashboard | B3: Should see | C3: Core | D3: Open Dashboard | E3: Menu → Core → Dashboard (/dashboard) | F3: The screen opens with no 'access denied' or error message. Lists load; an empty list says so. Buttons to add or change things appear only where this role should do that. | G3: dashboard.view | H3: Not run
A4: pharmacist:see:/approvals | B4: Should see | C4: Core | D4: Open Approvals | E4: Menu → Core → Approvals (/approvals) | F4: The screen opens with no 'access denied' or error message. Lists load; an empty list says so. Buttons to add or change things appear only where this role should do that. | H4: Not run
A5: pharmacist:see:/health-pulse | B5: Should see | C5: Core | D5: Open Health Pulse | E5: Menu → Core → Health Pulse (/health-pulse) | F5: The screen opens with no 'access denied' or error message. Lists load; an empty list says so. Buttons to add or change things appear only where this role should do that. | G5: dashboard.view | H5: Not run
A6: pharmacist:see:/ward-stock | B6: Should see | C6: Diagnostics | D6: Open Ward Stock | E6: Menu → Diagnostics → Ward Stock (/ward-stock) | F6: The screen opens with no 'access denied' or error message. Lists load; an empty list says so. Buttons to add or change things appear only where this role should do that. (Hidden if the hospital has this module switched off.) | G6: pharmacy.stores.manage | H6: Not run
A7: pharmacist:see:/pharmacy | B7: Should see | C7: Diagnostics | D7: Open Pharmacy | E7: Menu → Diagnostics → Pharmacy (/pharmacy) | F7: The screen opens with no 'access denied' or error message. Lists load; an empty list says so. Buttons to add or change things appear only where this role should do that. | G7: pharmacy.prescriptions.list | H7: Not run
A8: pharmacist:see:/pharmacy/finance | B8: Should see | C8: Diagnostics | D8: Open Pharmacy Finance | E8: Menu → Diagnostics → Pharmacy Finance (/pharmacy/finance) | F8: The screen opens with no 'access denied' or error message. Lists load; an empty list says so. Buttons to add or change things appear only where this role should do that. | G8: pharmacy_finance.cash_drawer.view, pharmacy_finance.cash_drawer.open, pharmacy_finance.cash_drawer.close… | H8: Not run
A9: pharmacist:see:/pharmacy/fulfilment | B9: Should see | C9: Diagnostics | D9: Open Fulfilment Queue | E9: Menu → Diagnostics → Fulfilment Queue (/pharmacy/fulfilment) | F9: The screen opens with no 'access denied' or error message. Lists load; an empty list says so. Buttons to add or change things appear only where this role should do that. (Hidden if the hospital has this module switched off.) | G9: pharmacy.fulfilment.pick | H9: Not run
A10: pharmacist:see:/pharmacy/deliveries | B10: Should see | C10: Diagnostics | D10: Open Home Deliveries | E10: Menu → Diagnostics → Home Deliveries (/pharmacy/deliveries) | F10: The screen opens with no 'access denied' or error message. Lists load; an empty list says so. Buttons to add or change things appear only where this role should do that. (Hidden if the hospital has this module switched off.) | G10: pharmacy.deliveries.view | H10: Not run
A11: pharmacist:see:/pharmacy/dispatch | B11: Should see | C11: Diagnostics | D11: Open Collection Counter | E11: Menu → Diagnostics → Collection Counter (/pharmacy/dispatch) | F11: The screen opens with no 'access denied' or error message. Lists load; an empty list says so. Buttons to add or change things appear only where this role should do that. (Hidden if the hospital has this module switched off.) | G11: pharmacy.fulfilment.dispatch | H11: Not run
A12: pharmacist:see:/indent | B12: Should see | C12: Finance | D12: Open Indent & Store | E12: Menu → Finance → Indent & Store (/indent) | F12: The screen opens with no 'access denied' or error message. Lists load; an empty list says so. Buttons to add or change things appear only where this role should do that. | G12: indent.list | H12: Not run
A13: pharmacist:see:/materials | B13: Should see | C13: Finance | D13: Open Materials | E13: Menu → Finance → Materials (/materials) | F13: The screen opens with no 'access denied' or error message. Lists load; an empty list says so. Buttons to add or change things appear only where this role should do that. | G13: indent.list, assets.list, procurement.vendors.list… | H13: Not run
A14: pharmacist:see:/lms | B14: Should see | C14: Operations | D14: Open Learning (LMS) | E14: Menu → Operations → Learning (LMS) (/lms) | F14: The screen opens with no 'access denied' or error message. Lists load; an empty list says so. Buttons to add or change things appear only where this role should do that. | G14: lms.my_learning.view | H14: Not run
A15: pharmacist:see:/regulatory | B15: Should see | C15: Compliance | D15: Open Regulatory Compliance | E15: Menu → Compliance → Regulatory Compliance (/regulatory) | F15: The screen opens with no 'access denied' or error message. Lists load; an empty list says so. Buttons to add or change things appear only where this role should do that. | G15: regulatory.dashboard.view | H15: Not run
A16: pharmacist:see:/reports | B16: Should see | C16: Compliance | D16: Open Reports Center | E16: Menu → Compliance → Reports Center (/reports) | F16: The screen opens with no 'access denied' or error message. Lists load; an empty list says so. Buttons to add or change things appear only where this role should do that. | G16: analytics.view, billing.reports.view, quality.indicators.list… | H16: Not run
A17: pharmacist:see:/admin/documents | B17: Should see | C17: Administration | D17: Open Documents & Printing | E17: Menu → Administration → Admin → Documents & Printing (/admin/documents) | F17: The screen opens with no 'access denied' or error message. Lists load; an empty list says so. Buttons to add or change things appear only where this role should do that. | G17: documents.templates.list | H17: Not run
A18: pharmacist:menu | B18: Must not see | C18: Menu | D18: Menu shows only this role's screens | E18: Look through every menu group. | F18: These must NOT be in the menu: Token Board, Token Console, Patients, OPD Queue, Appointments, Telemedicine, Doctor Sign-offs, Emergency, Order Sets, Chronic Care, Home healthcare, Home visits, Lab, Radiology, Blood Bank, IPD, Care View, Case sheet review, ICU, Nurse Activities, Operation Theatre, Diet & Kitchen, Bedside Portal, Billing, Insurance & TPA, Procurement, Payroll, Front Office, Smart Scheduling, Command Center, Communications, Camp Management, Ambulance, Housekeeping, CSSD, Facilities Management, Biomedical Engineering, Security, HR & Staffing, Medical Records, Clinical Knowledge, Directory, Hospital groups, Inter-hospital transfers, Inter-hospital stock, Marketing, Health packages, Testimonials, Micro-site settings, Quality, Infection Control, Consent Management, Analytics & Dashboards, Audit Trail, Utilization Review, Case Management, Ophthalmology, Dental, Cath Lab, Endoscopy, Psychiatry, Physical Medicine, Palliative Care, Maternity, Other Specialties, Clinical trials, Long-term care, Occupational Health, Users, Doctors, Roles & Permissions, Access Groups, Single Sign-On, Access Requests, NABH Indicators, Setup Center, Onboarding workbook, Settings, Document Templates, Built-in Pipelines, Forms, Test cycles, API keys, Webhooks, Doctor Schedules, Retrospective Entry, Device Integration, Paired Devices, Queues, Message Simulator. | H18: Not run
A19: pharmacist:url:/admin/users | B19: Must not see | C19: Administration | D19: Typing the address of Users | E19: Type app.medbrains.in/admin/users into the address bar. | F19: You get an 'access denied' page or are sent back — none of that screen's data is shown, even briefly. | G19: admin.users.list | H19: Not run
A20: pharmacist:url:/audit | B20: Must not see | C20: Compliance | D20: Typing the address of Audit Trail | E20: Type app.medbrains.in/audit into the address bar. | F20: You get an 'access denied' page or are sent back — none of that screen's data is shown, even briefly. | G20: audit.log.view | H20: Not run
A21: pharmacist:url:/billing | B21: Must not see | C21: Finance | D21: Typing the address of Billing | E21: Type app.medbrains.in/billing into the address bar. | F21: You get an 'access denied' page or are sent back — none of that screen's data is shown, even briefly. | G21: billing.invoices.list | H21: Not run
A22: pharmacist:url:/mrd | B22: Must not see | C22: Operations | D22: Typing the address of Medical Records | E22: Type app.medbrains.in/mrd into the address bar. | F22: You get an 'access denied' page or are sent back — none of that screen's data is shown, even briefly. | H22: Not run
A23: pharmacist:wf:dispense-a-prescription | B23: Workflow | C23: Pharmacy | D23: Dispense a prescription | E23: (As test_doctor, prescribe two medicines.) Pharmacy → prescription queue → open → dispense from the oldest-expiry batch. | F23: Stock reduces from the chosen batch; a label can be printed; the items are billed. | H23: Not run
A24: pharmacist:wf:controlled-schedule-h-drug | B24: Workflow | C24: Pharmacy | D24: Controlled / Schedule H drug | E24: Dispense a Schedule H or NDPS drug. | F24: The schedule badge shows; NDPS needs a register entry before it can be dispensed. | H24: Not run
A25: pharmacist:wf:counter-sale-and-a-return | B25: Workflow | C25: Pharmacy | D25: Counter sale and a return | E25: Pharmacy → POS → sell an OTC item → then return it. | F25: The sale prints a receipt; the return restores stock and refunds at the original price. | H25: Not run

Sheet Billing Clerk
A1: Case | B1: Type | C1: Area | D1: What to test | E1: Steps | F1: Expected | G1: Permission | H1: Result | I1: Tester | J1: Date | K1: Notes
A2: billing_clerk:sign-in | B2: Sign in | C2: Sign in | D2: Sign in as Billing Clerk | E2: app.medbrains.in → hospital code AMH → username test_billing_clerk and the password from your test-accounts file. | F2: You are signed in; the header shows 'TEST - Billing Clerk'; you land on a page you can use (not an error). | H2: Not run
A3: billing_clerk:see:/dashboard | B3: Should see | C3: Core | D3: Open Dashboard | E3: Menu → Core → Dashboard (/dashboard) | F3: The screen opens with no 'access denied' or error message. Lists load; an empty list says so. Buttons to add or change things appear only where this role should do that. | G3: dashboard.view | H3: Not run
A4: billing_clerk:see:/approvals | B4: Should see | C4: Core | D4: Open Approvals | E4: Menu → Core → Approvals (/approvals) | F4: The screen opens with no 'access denied' or error message. Lists load; an empty list says so. Buttons to add or change things appear only where this role should do that. | H4: Not run
A5: billing_clerk:see:/health-pulse | B5: Should see | C5: Core | D5: Open Health Pulse | E5: Menu → Core → Health Pulse (/health-pulse) | F5: The screen opens with no 'access denied' or error message. Lists load; an empty list says so. Buttons to add or change things appear only where this role should do that. | G5: dashboard.view | H5: Not run
A6: billing_clerk:see:/patients | B6: Should see | C6: Clinical | D6: Open Patients | E6: Menu → Clinical → Patients (/patients) | F6: The screen opens with no 'access denied' or error message. Lists load; an empty list says so. Buttons to add or change things appear only where this role should do that. | G6: patients.list | H6: Not run
A7: billing_clerk:see:/emergency | B7: Should see | C7: Clinical | D7: Open Emergency | E7: Menu → Clinical → Emergency (/emergency) | F7: The screen opens with no 'access denied' or error message. Lists load; an empty list says so. Buttons to add or change things appear only where this role should do that. | G7: emergency.visits.list | H7: Not run
A8: billing_clerk:see:/pharmacy/finance | B8: Should see | C8: Diagnostics | D8: Open Pharmacy Finance | E8: Menu → Diagnostics → Pharmacy Finance (/pharmacy/finance) | F8: The screen opens with no 'access denied' or error message. Lists load; an empty list says so. Buttons to add or change things appear only where this role should do that. | G8: pharmacy_finance.cash_drawer.view, pharmacy_finance.cash_drawer.open, pharmacy_finance.cash_drawer.close… | H8: Not run
A9: billing_clerk:see:/billing | B9: Should see | C9: Finance | D9: Open Billing | E9: Menu → Finance → Billing (/billing) | F9: The screen opens with no 'access denied' or error message. Lists load; an empty list says so. Buttons to add or change things appear only where this role should do that. | G9: billing.invoices.list | H9: Not run
